Workbook

Sheet Transaction Summary
A1: ABB / Rotork M&A Transaction Model
A2: As of 06-Sep-2026 | USD $m unless stated | Offer terms in GBP / pence
A3: Primary sources: ABB announcement (S01), Rotork Scheme Document (S02), latest deal status (S03) and transaction-date FX (S09).
A4: Transaction Overview | F4: Valuation & Key Outputs
A5: Acquirer | B5: ABB Ltd | F5: Reported EV / Sales | G5: ='Transaction & Financing'!$C$54 -> 5.2540847
A6: Target | B6: Rotork plc | F6: Reported EV / adj. EBITDA | G6: ='Transaction & Financing'!$C$55 -> 19.466158
A7: Announcement date | B7: 46219 | F7: Model EV / Sales | G7: ='Transaction & Financing'!$C$56 -> 5.2501479
A8: Latest deal status | B8: Meetings approved 03-Sep-2026; Court sanction and remaining conditions outstanding | F8: Model EV / adj. EBITDA | G8: ='Transaction & Financing'!$C$57 -> 19.451573
A9: Expected completion | B9: H1 2027 | F9: Pre-synergy EV / EBITDA | G9: ='Transaction & Financing'!$C$58 -> 19.451573
A10: Offer structure | B10: Recommended all-cash scheme | F10: Base "mid-teens" multiple | G10: ='Transaction & Financing'!$C$60 -> 15
A11: Cash consideration | B11: 503 | F11: High implied EBITDA synergy | G11: ='Transaction & Financing'!$C$65 -> 110.38523
A12: Permitted dividend | B12: 3 | F12: Base implied EBITDA synergy | G12: ='Transaction & Financing'!$C$68 -> 84.178206
A13: Total potential shareholder value | B13: =B11+B12 -> 506 | F13: Low implied EBITDA synergy | G13: ='Transaction & Financing'!$C$67 -> 61.247056
A14: Unaffected share price | B14: 290.8 | F14: Funding sources / uses status | G14: =IF(ABS('Transaction & Financing'!$B$82)<0.1,"OK","ERROR") -> OK
A15: 3-month VWAP | B15: 309.2 | F15: Standalone ABB EPS — FY27E PF / run-rate | G15: ='Accretion-Dilution'!$B$21 -> 2.9496976
A16: Premium to unaffected | B16: =B11/B14-1 -> 0.72971114 | F16: Pro forma ABB EPS — FY27E PF / run-rate | G16: ='Accretion-Dilution'!$B$23 -> 3.0210814
A17: Premium to 3-month VWAP | B17: =B11/B15-1 -> 0.62677878 | F17: FY27E PF EPS accretion / (dilution) | G17: ='Accretion-Dilution'!$B$25 -> 0.024200378
A18: Fully diluted shares | B18: ='Transaction & Financing'!$B$9 -> 822.25446 | F18: FY28E EPS accretion / (dilution) | G18: ='Accretion-Dilution'!$C$25 -> 0.035502357
A19: Equity purchase price | B19: ='Transaction & Financing'!$C$37 -> 5573.4686 | F19: Model accretion basis | G19: ='Accretion-Dilution'!$B$27 -> FY27E full-year PF / run-rate
A20: Implied enterprise value | B20: ='Transaction & Financing'!$C$48 -> 5503.4759 | F20: Breakeven EBITDA synergy | G20: ='Accretion-Dilution'!$B$28 -> N/A – accretive pre-synergy
A21: GBP / USD FX (16-Jul-2026) | B21: ='Transaction & Financing'!$B$10 -> 1.34757
A22: Adviser(s) | B22: ABB: Barclays | Rotork: J.P. Morgan Cazenove, Rothschild & Co, Jefferies, Morgan Stanley
A25: Strategic Rationale
A26: • Expands ABB's process automation portfolio into flow control and electric actuation.
A27: • Adds Rotork's installed base and aftermarket exposure across process industries.
A28: • Creates cross-selling opportunities through ABB's global automation and electrification channels.
A29: • Rotork is expected to operate as a separate division within ABB's Process Automation business.
A31: Key Risks
A32: Premium / valuation | B32: High entry valuation: 62.7% premium to 3-month VWAP and 19.5x EV / adjusted EBITDA.
A33: Synergy / integration | B33: Synergy range is inferred from ABB's 'mid-teens' post-synergy multiple rather than quantified guidance.
A34: Closing / financing | B34: Court / regulatory conditions remain outstanding; financing costs may affect completion economics.

Sheet ABB Financials
A1: ABB Financial Profile
A2: USD $m except per-share data | FY24A-FY25A reported | H1 2026A actual | FY26E-FY28E estimates
A3: Sources: FY24A–FY25A = S07 | H1 2026A = S06 | FY26E–FY28E = model assumptions (S16). Full references in Sensitivity & Sources.
A4: Operating & Earnings Profile ($m except per share data)
A5: Metric | B5: FY24A | C5: FY25A | D5: H1 2026A | E5: FY26E | F5: FY27E | G5: FY28E
A6: Revenue | B6: 30583 | C6: 33220 | D6: 18209 | E6: =D6*$B$32 -> 36418 | F6: =E6*(1+$B$33) -> 38238.9 | G6: =F6*(1+$B$34) -> 40150.845
A7: Revenue growth | B7: – | C7: =C6/B6-1 -> 0.086224373 | D7: – | E7: =E6/C6-1 -> 0.096267309 | F7: =F6/E6-1 -> 0.05 | G7: =G6/F6-1 -> 0.05
A8: Income from operations | B8: 4735 | C8: 6047 | D8: 3365 | E8: =D8*$B$32 -> 6730 | F8: =E8*(1+$B$33) -> 7066.5 | G8: =F8*(1+$B$34) -> 7419.825
A9: Operational EBITA | B9: 5572 | C9: 6314 | D9: 3974 | E9: =D9*$B$32 -> 7948 | F9: =E9*(1+$B$33) -> 8345.4 | G9: =F9*(1+$B$34) -> 8762.67
A10: Operational EBITA margin | B10: =B9/B6 -> 0.18219272 | C10: =C9/C6 -> 0.19006623 | D10: =D9/D6 -> 0.21824373 | E10: =E9/E6 -> 0.21824373 | F10: =F9/F6 -> 0.21824373 | G10: =G9/G6 -> 0.21824373
A11: Net finance income / (expense) | B11: 132 | C11: 117 | D11: 52 | E11: =D11*$B$32 -> 104 | F11: =E11 -> 104 | G11: =F11 -> 104
A12: Income tax expense | B12: -1197 | C12: -1570 | D12: -883 | E12: =-(E8+E11)*E13 -> -1766 | F12: =-(F8+F11)*F13 -> -1852.9562 | G12: =-(G8+G11)*G13 -> -1944.2603
A13: Effective tax rate | B13: =-B12/(B8+B11) -> 0.24594206 | C13: =-C12/(C8+C11) -> 0.25470474 | D13: =-D12/(D8+D11) -> 0.25841381 | E13: =D13 -> 0.25841381 | F13: =E13 -> 0.25841381 | G13: =F13 -> 0.25841381
A14: Net income attributable to ABB | B14: 3935 | C14: 4734 | D14: 2555 | E14: =D14*$B$32 -> 5110 | F14: =E14*(1+$B$33) -> 5365.5 | G14: =F14*(1+$B$34) -> 5633.775
A15: Diluted shares | B15: 1851 | C15: 1831 | D15: 1819 | E15: =D15 -> 1819 | F15: =E15 -> 1819 | G15: =F15 -> 1819
A16: Diluted EPS | B16: 2.13 | C16: 2.59 | D16: 1.4 | E16: =E14/E15 -> 2.8092358 | F16: =F14/F15 -> 2.9496976 | G16: =G14/G15 -> 3.0971825
A17: Cash flow from operating activities | B17: 4675 | C17: 5469 | D17: 2179 | E17: =D17*$B$32 -> 4358 | F17: =E17*(1+$B$33) -> 4575.9 | G17: =F17*(1+$B$34) -> 4804.695
A18: Free cash flow | B18: 3937 | C18: 4566 | D18: 2131 | E18: =D18*$B$32 -> 4262 | F18: =E18*(1+$B$33) -> 4475.1 | G18: =F18*(1+$B$34) -> 4698.855
A21: Capital Structure ($m)
A22: Cash and equivalents | B22: 4326 | C22: 4640 | D22: 3867
A23: Marketable securities / short-term investments | B23: 1334 | C23: 1981 | D23: 1990
A24: Gross debt | B24: 6940 | C24: 8304 | D24: 8177
A25: Net debt (incl. marketable securities) | B25: 1280 | C25: 1683 | D25: =D24-D22-D23 -> 2320
A26: Net debt / Operational EBITA | B26: =B25/B9 -> 0.22972003 | C26: =C25/C9 -> 0.26655052 | D26: =D25/D9 -> 0.58379467
A29: Forecast Assumptions & Conventions
A30: Forecast basis | B30: FY26E annualized from H1 2026A; FY27E/FY28E use 5.0% growth
A31: Units | B31: $m except per-share data
A32: FY26E annualisation factor (x) | B32: 2
A33: FY27E net income / operating growth | B33: 0.05
A34: FY28E net income / operating growth | B34: 0.05
A35: Latest diluted shares (m) | B35: =D15 -> 1819
A36: Pro forma tax rate | B36: =D13 -> 0.25841381
A38: Operational EBITA is ABB's reported alternative performance measure.
A39: FY26E annualises H1 2026A; FY27E-FY28E apply the stated growth assumptions.
A40: Source IDs above map to the full Source Log on Sensitivity & Sources.

Sheet Rotork Financials
A1: Rotork Financial Profile
A2: GBP £m except per-share data | FY24A-FY25A reported | H1 2026A actual | FY26E-FY28E estimates
A3: Sources: FY24A–FY25A = S05 | H1 2026A = S04 | FY26E–FY28E = model assumptions (S16). Full references in Sensitivity & Sources.
A4: Operating & Earnings Profile (£m except per-share data)
A5: Metric | B5: FY24A | C5: FY25A | D5: H1 2026A | E5: FY26E | F5: FY27E | G5: FY28E
A6: Revenue | B6: 754.4 | C6: 777.3 | D6: 367.2 | E6: =D6*$B$36 -> 734.4 | F6: =E6*(1+$B$37) -> 771.12 | G6: =F6*(1+$B$38) -> 809.676
A7: Revenue growth | B7: – | C7: =C6/B6-1 -> 0.030355249 | D7: – | E7: =E6/C6-1 -> -0.055191046 | F7: =F6/E6-1 -> 0.05 | G7: =G6/F6-1 -> 0.05
A8: Reported operating profit | B8: 135.9 | C8: 157.1 | D8: 72 | E8: =D8*$B$36 -> 144 | F8: =E8*(1+$B$37) -> 151.2 | G8: =F8*(1+$B$38) -> 158.76
A9: Adjusted operating profit | B9: 178.4 | C9: 191.5 | D9: 82.2 | E9: =D9*$B$36 -> 164.4 | F9: =E9*(1+$B$37) -> 172.62 | G9: =F9*(1+$B$38) -> 181.251
A10: Adjusted operating margin | B10: =B9/B6 -> 0.23647932 | C10: =C9/C6 -> 0.24636562 | D10: =D9/D6 -> 0.22385621 | E10: =E9/E6 -> 0.22385621 | F10: =F9/F6 -> 0.22385621 | G10: =G9/G6 -> 0.22385621
A11: Depreciation | B11: 14.3 | C11: 15.3 | D11: 7.1 | E11: =D11*$B$36 -> 14.2 | F11: =E11*(1+$B$37) -> 14.91 | G11: =F11*(1+$B$38) -> 15.6555
A12: Acquired intangible amortisation | B12: 2.6 | C12: 3 | D12: 1.6 | E12: =D12*$B$36 -> 3.2 | F12: =E12*(1+$B$37) -> 3.36 | G12: =F12*(1+$B$38) -> 3.528
A13: Adjusted EBITDA proxy | B13: =SUM(B9,B11:B12) -> 195.3 | C13: =SUM(C9,C11:C12) -> 209.8 | D13: =SUM(D9,D11:D12) -> 90.9 | E13: =SUM(E9,E11:E12) -> 181.8 | F13: =SUM(F9,F11:F12) -> 190.89 | G13: =SUM(G9,G11:G12) -> 200.4345
A14: Reported profit before tax | B14: 140.5 | C14: 157.9 | D14: 71.4 | E14: =D14*$B$36 -> 142.8 | F14: =E14*(1+$B$37) -> 149.94 | G14: =F14*(1+$B$38) -> 157.437
A15: Net finance income / (expense) | B15: 4.6 | C15: 0.8 | D15: -0.6 | E15: =D15*$B$36 -> -1.2 | F15: =E15 -> -1.2 | G15: =F15 -> -1.2
A16: Income tax expense | B16: -35.7 | C16: -41 | D16: -16.4 | E16: =D16*$B$36 -> -32.8 | F16: =E16*(1+$B$37) -> -34.44 | G16: =F16*(1+$B$38) -> -36.162
A17: Effective tax rate | B17: =-B16/B14 -> 0.25409253 | C17: =-C16/C14 -> 0.25965801 | D17: =-D16/D14 -> 0.22969188 | E17: =-E16/E14 -> 0.22969188 | F17: =-F16/F14 -> 0.22969188 | G17: =-G16/G14 -> 0.22969188
A18: Net profit attributable to ordinary shareholders | B18: 103.6 | C18: 115.4 | D18: 54.7 | E18: =D18*$B$36 -> 109.4 | F18: =E18*(1+$B$37) -> 114.87 | G18: =F18*(1+$B$38) -> 120.6135
A19: Diluted shares | B19: 857 | C19: 839.5 | D19: 822 | E19: =D19 -> 822 | F19: =E19 -> 822 | G19: =F19 -> 822
A20: Diluted EPS | B20: 12.1 | C20: 13.7 | D20: 6.7 | E20: =E18/E19*100 -> 13.309002 | F20: =F18/F19*100 -> 13.974453 | G20: =G18/G19*100 -> 14.673175
A21: Adjusted net profit attributable | B21: 135.6 | C21: 142.2 | D21: 60.7 | E21: =D21*$B$36 -> 121.4 | F21: =E21*(1+$B$37) -> 127.47 | G21: =F21*(1+$B$38) -> 133.8435
A22: Adjusted diluted EPS | B22: 15.8 | C22: 16.9 | D22: 7.4 | E22: =E21/E19*100 -> 14.768856 | F22: =F21/F19*100 -> 15.507299 | G22: =G21/G19*100 -> 16.282664
A26: Balance Sheet & Share Data (£m except shares)
A27: Cash and short-term deposits | B27: 150 | C27: 110 | D27: 70
A28: Interest-bearing loans & borrowings | B28: 24.7 | C28: 44.7 | D28: 44.7
A29: Lease liabilities | C29: 22.7 | D29: 22.7
A30: Net cash (ex leases) | B30: =B27-B28 -> 125.3 | C30: =C27-C28 -> 65.3 | D30: =D27-D28 -> 25.3
A31: Net cash (incl leases) | B31: =B27-B28-B29 -> 125.3 | C31: =C27-C28-C29 -> 42.6 | D31: =D27-D28-D29 -> 2.6
A33: Forecast Assumptions & Conventions
A34: Forecast basis | B34: FY26E annualized from H1 2026A; FY27E/FY28E use 5.0% growth
A35: Units | B35: £m except per-share data
A36: FY26E annualisation factor (x) | B36: 2
A37: FY27E growth assumption | B37: 0.05
A38: FY28E growth assumption | B38: 0.05
A40: Adjusted EBITDA proxy = adjusted operating profit + depreciation + acquired intangible amortisation.
A41: FY26E annualises H1 2026A; FY27E-FY28E apply the stated growth assumptions.
A42: Source IDs above map to the full Source Log on Sensitivity & Sources.

Sheet Transaction & Financing
A1: ABB / Rotork Transaction Mechanics & Financing
A2: Offer terms in GBP / pence | Transaction values translated to USD at 16-Jul-2026 FX
A3: Sources: transaction terms and target balance sheet (S01–S04), ABB funding (S08), FX (S09) and model assumptions (S10–S17).
A4: Transaction Inputs
A5: Cash consideration (GBP / share) | B5: 5.03
A6: Permitted dividend (GBP / share) | B6: 0.03
A7: Unaffected share price (GBP / share) | B7: 2.908
A8: 3-month VWAP (GBP / share) | B8: 3.092
A9: Fully diluted Rotork shares (m) | B9: 822.25446
A10: GBP / USD FX (16-Jul-2026) | B10: 1.34757
A11: Transaction fees ($m) | B11: 25
A12: Target cash acquired (£m, H1 2026) | B12: 70
A13: Target interest-bearing debt (£m, H1 2026) | B13: 44.7
A14: Target lease liabilities (£m, H1 2026) | B14: 22.7
A15: Target pension deficit (£m, H1 2026) | B15: 0.6
A16: Announcement net cash incl. leases (£m, 31-Mar-2026) | B16: 57
A17: Announcement pension deficit (£m, 31-Dec-2025) | B17: 2
A20: Financing Assumptions
A21: ABB Robotics disposal net cash proceeds ($m) | B21: 4800
A22: ABB existing cash used ($m) | B22: 500
A23: Incremental debt / facilities ($m) | B23: =MAX(B76-B21-B22,0) -> 358.70498
A24: Base borrowing rate | B24: 0.045
A25: Foregone cash yield | B25: 0.035
A26: Pro forma tax rate | B26: ='ABB Financials'!$D$13 -> 0.25841381
A27: Low “mid-teens” EV / EBITDA interpretation | B27: 14
A28: Base “mid-teens” EV / EBITDA interpretation | B28: 15
A29: High “mid-teens” EV / EBITDA interpretation | B29: 16
A30: Year 1 synergy realization | B30: 0
A31: Year 2 synergy realization | B31: 1
A34: Purchase Price Analysis (GBP / USD)
A35: Cash consideration per share | B35: =B5 -> 5.03 | C35: =B35*B10 -> 6.7782771
A36: Fully diluted shares | B36: =B9 -> 822.25446 | C36: =B36 -> 822.25446
A37: Implied equity purchase price | B37: =B35*B36 -> 4135.94 | C37: =B37*B10 -> 5573.4686
A38: Add: debt assumed | B38: =B13 -> 44.7 | C38: =B38*B10 -> 60.236379
A39: Less: cash acquired | B39: =-B12 -> -70 | C39: =B39*B10 -> -94.3299
A40: Add: lease liabilities | B40: =B14 -> 22.7 | C40: =B40*B10 -> 30.589839
A41: Add: pension deficit | B41: =B15 -> 0.6 | C41: =B41*B10 -> 0.808542
A42: Implied EV from latest H1 balance sheet | B42: =SUM(B37:B41) -> 4133.94 | C42: =SUM(C37:C41) -> 5570.7735
A44: Announcement EV bridge — equity purchase price | B44: =B37 -> 4135.94 | C44: =B44*B10 -> 5573.4686
A45: Less: net cash incl. leases (31-Mar-2026) | B45: =-B16 -> -57 | C45: =B45*B10 -> -76.81149
...

Sheet Accretion-Dilution
A1: ABB / Rotork Pro Forma EPS Accretion / (Dilution)
A2: USD $m except per-share data | FY27E shown on full-year pro forma / run-rate basis | FY28E first full post-close year
A3: Sources: linked ABB / Rotork forecasts, transaction financing assumptions and EPS bridge methodology (S04–S18).
A4: Pro Forma EPS Bridge
A5: Metric | B5: FY27E PF / run-rate | C5: FY28E
A6: ABB standalone net income | B6: ='ABB Financials'!$F$14 -> 5365.5 | C6: ='ABB Financials'!$G$14 -> 5633.775
A7: Rotork standalone net income (£m) | B7: ='Rotork Financials'!$F$18 -> 114.87 | C7: ='Rotork Financials'!$G$18 -> 120.6135
A8: GBP / USD FX | B8: ='Transaction & Financing'!$B$10 -> 1.34757 | C8: ='Transaction & Financing'!$B$10 -> 1.34757
A9: Rotork standalone net income ($m) | B9: =B7*B8 -> 154.79537 | C9: =C7*C8 -> 162.53513
A10: EBITDA synergies realized | B10: ='Transaction & Financing'!$C$68*'Transaction & Financing'!$B$30 -> 0 | C10: ='Transaction & Financing'!$C$68*'Transaction & Financing'!$B$31 -> 84.178206
A11: After-tax EBITDA synergies | B11: =B10*(1-'Transaction & Financing'!$B$26) -> 0 | C11: =C10*(1-'Transaction & Financing'!$B$26) -> 62.425395
A12: Incremental debt / facilities | B12: ='Transaction & Financing'!$B$80 -> 358.70498 | C12: ='Transaction & Financing'!$B$80 -> 358.70498
A13: Borrowing rate | B13: ='Transaction & Financing'!$B$24 -> 0.045 | C13: ='Transaction & Financing'!$B$24 -> 0.045
A14: Incremental interest expense | B14: =B12*B13 -> 16.141724 | C14: =C12*C13 -> 16.141724
A15: Foregone cash interest | B15: ='Transaction & Financing'!$B$79*'Transaction & Financing'!$B$25 -> 17.5 | C15: ='Transaction & Financing'!$B$79*'Transaction & Financing'!$B$25 -> 17.5
A16: After-tax financing drag | B16: =SUM(B14:B15)*(1-'Transaction & Financing'!$B$26) -> 24.948238 | C16: =SUM(C14:C15)*(1-'Transaction & Financing'!$B$26) -> 24.948238
A17: Other recurring adjustments | B17: =0 -> 0 | C17: =0 -> 0
A18: Pro forma net income before synergies | B18: =B6+B9-B16+B17 -> 5495.3471 | C18: =C6+C9-C16+C17 -> 5771.3619
A19: Pro forma net income after synergies | B19: =B18+B11 -> 5495.3471 | C19: =C18+C11 -> 5833.7873
A20: ABB diluted shares (m) | B20: ='ABB Financials'!$F$15 -> 1819 | C20: ='ABB Financials'!$G$15 -> 1819
A21: Standalone ABB EPS | B21: =B6/B20 -> 2.9496976 | C21: =C6/C20 -> 3.0971825
A22: Pro forma EPS before synergies | B22: =B18/B20 -> 3.0210814 | C22: =C18/C20 -> 3.1728213
A23: Pro forma EPS after synergies | B23: =B19/B20 -> 3.0210814 | C23: =C19/C20 -> 3.2071398
A24: EPS accretion / (dilution) before synergies | B24: =B22/B21-1 -> 0.024200378 | C24: =C22/C21-1 -> 0.024421795
A25: EPS accretion / (dilution) after synergies | B25: =B23/B21-1 -> 0.024200378 | C25: =C23/C21-1 -> 0.035502357
A26: Company indicated accretion timing | B26: ="No explicit EPS accretion timing guidance" -> No explicit EPS accretion timing guidance | C26: ="No explicit EPS accretion timing guidance" -> No explicit EPS accretion timing guidance
A27: Model accretion basis | B27: FY27E full-year PF / run-rate | C27: FY28E full-year
A28: Breakeven EBITDA synergy ($m) | B28: =IF(B24>=0,"N/A – accretive pre-synergy",MAX((B16-B9)/(1-'Transaction & Financing'!$B$26),0)) -> N/A – accretive pre-synergy | C28: =IF(C24>=0,"N/A – accretive pre-synergy",MAX((C16-C9)/(1-'Transaction & Financing'!$B$26),0)) -> N/A – accretive pre-synergy
A30: Key Assumptions
A31: EPS basis | B31: Reported net income and diluted shares.
A32: Synergy timing | B32: 0% in FY27E; 100% in FY28E.
A33: Funding | B33: Robotics proceeds and $500m ABB cash used before incremental debt.
A34: Purchase accounting | B34: No PPA amortisation, integration costs or dividend adjustments.
A35: Sources | B35: See Sensitivity & Sources.

Sheet Sensitivity & Sources
A1: ABB / Rotork Sensitivity & Sources
A2: FY28E EPS accretion sensitivity to EBITDA synergies and incremental borrowing cost
A4: EPS Accretion Sensitivity — FY28E
A5: Synergy ($m) / Borrowing rate | B5: 0.035 | C5: 0.045 | D5: 0.055 | E5: 0.065 | F5: Base case
A6: =0 -> 0 | B6: =((('Accretion-Dilution'!$C$6+'Accretion-Dilution'!$C$9+($A6*(1-'Transaction & Financing'!$B$26))-(('Transaction & Financing'!$B$80*B$5)+'Transaction & Financing'!$B$79*'Transaction & Financing'!$B$25)*(1-'Transaction & Financing'!$B$26))/'Accretion-Dilution'!$C$20)/'Accretion-Dilution'!$C$21)-1 -> 0.024893966 | C6: =((('Accretion-Dilution'!$C$6+'Accretion-Dilution'!$C$9+($A6*(1-'Transaction & Financing'!$B$26))-(('Transaction & Financing'!$B$80*C$5)+'Transaction & Financing'!$B$79*'Transaction & Financing'!$B$25)*(1-'Transaction & Financing'!$B$26))/'Accretion-Dilution'!$C$20)/'Accretion-Dilution'!$C$21)-1 -> 0.024421795 | D6: =((('Accretion-Dilution'!$C$6+'Accretion-Dilution'!$C$9+($A6*(1-'Transaction & Financing'!$B$26))-(('Transaction & Financing'!$B$80*D$5)+'Transaction & Financing'!$B$79*'Transaction & Financing'!$B$25)*(1-'Transaction & Financing'!$B$26))/'Accretion-Dilution'!$C$20)/'Accretion-Dilution'!$C$21)-1 -> 0.023949623 | E6: =((('Accretion-Dilution'!$C$6+'Accretion-Dilution'!$C$9+($A6*(1-'Transaction & Financing'!$B$26))-(('Transaction & Financing'!$B$80*E$5)+'Transaction & Financing'!$B$79*'Transaction & Financing'!$B$25)*(1-'Transaction & Financing'!$B$26))/'Accretion-Dilution'!$C$20)/'Accretion-Dilution'!$C$21)-1 -> 0.023477452 | F6: =((('Accretion-Dilution'!$C$6+'Accretion-Dilution'!$C$9+($A6*(1-'Transaction & Financing'!$B$26))-(('Transaction & Financing'!$B$80*'Transaction & Financing'!$B$24)+'Transaction & Financing'!$B$79*'Transaction & Financing'!$B$25)*(1-'Transaction & Financing'!$B$26))/'Accretion-Dilution'!$C$20)/'Accretion-Dilution'!$C$21)-1 -> 0.024421795
A7: ='Transaction & Financing'!$C$67 -> 61.247056 | B7: =((('Accretion-Dilution'!$C$6+'Accretion-Dilution'!$C$9+($A7*(1-'Transaction & Financing'!$B$26))-(('Transaction & Financing'!$B$80*B$5)+'Transaction & Financing'!$B$79*'Transaction & Financing'!$B$25)*(1-'Transaction & Financing'!$B$26))/'Accretion-Dilution'!$C$20)/'Accretion-Dilution'!$C$21)-1 -> 0.032956051 | C7: =((('Accretion-Dilution'!$C$6+'Accretion-Dilution'!$C$9+($A7*(1-'Transaction & Financing'!$B$26))-(('Transaction & Financing'!$B$80*C$5)+'Transaction & Financing'!$B$79*'Transaction & Financing'!$B$25)*(1-'Transaction & Financing'!$B$26))/'Accretion-Dilution'!$C$20)/'Accretion-Dilution'!$C$21)-1 -> 0.032483879 | D7: =((('Accretion-Dilution'!$C$6+'Accretion-Dilution'!$C$9+($A7*(1-'Transaction & Financing'!$B$26))-(('Transaction & Financing'!$B$80*D$5)+'Transaction & Financing'!$B$79*'Transaction & Financing'!$B$25)*(1-'Transaction & Financing'!$B$26))/'Accretion-Dilution'!$C$20)/'Accretion-Dilution'!$C$21)-1 -> 0.032011708 | E7: =((('Accretion-Dilution'!$C$6+'Accretion-Dilution'!$C$9+($A7*(1-'Transaction & Financing'!$B$26))-(('Transaction & Financing'!$B$80*E$5)+'Transaction & Financing'!$B$79*'Transaction & Financing'!$B$25)*(1-'Transaction & Financing'!$B$26))/'Accretion-Dilution'!$C$20)/'Accretion-Dilution'!$C$21)-1 -> 0.031539537 | F7: =((('Accretion-Dilution'!$C$6+'Accretion-Dilution'!$C$9+($A7*(1-'Transaction & Financing'!$B$26))-(('Transaction & Financing'!$B$80*'Transaction & Financing'!$B$24)+'Transaction & Financing'!$B$79*'Transaction & Financing'!$B$25)*(1-'Transaction & Financing'!$B$26))/'Accretion-Dilution'!$C$20)/'Accretion-Dilution'!$C$21)-1 -> 0.032483879
A8: ='Transaction & Financing'!$C$66 -> 84.178206 | B8: =((('Accretion-Dilution'!$C$6+'Accretion-Dilution'!$C$9+($A8*(1-'Transaction & Financing'!$B$26))-(('Transaction & Financing'!$B$80*B$5)+'Transaction & Financing'!$B$79*'Transaction & Financing'!$B$25)*(1-'Transaction & Financing'!$B$26))/'Accretion-Dilution'!$C$20)/'Accretion-Dilution'!$C$21)-1 -> 0.035974528 | C8: =((('Accretion-Dilution'!$C$6+'Accretion-Dilution'!$C$9+($A8*(1-'Transaction & Financing'!$B$26))-(('Transaction & Financing'!$B$80*C$5)+'Transaction & Financing'!$B$79*'Transaction & Financing'!$B$25)*(1-'Transaction & Financing'!$B$26))/'Accretion-Dilution'!$C$20)/'Accretion-Dilution'!$C$21)-1 -> 0.035502357 | D8: =((('Accretion-Dilution'!$C$6+'Accretion-Dilution'!$C$9+($A8*(1-'Transaction & Financing'!$B$26))-(('Transaction & Financing'!$B$80*D$5)+'Transaction & Financing'!$B$79*'Transaction & Financing'!$B$25)*(1-'Transaction & Financing'!$B$26))/'Accretion-Dilution'!$C$20)/'Accretion-Dilution'!$C$21)-1 -> 0.035030186 | E8: =((('Accretion-Dilution'!$C$6+'Accretion-Dilution'!$C$9+($A8*(1-'Transaction & Financing'!$B$26))-(('Transaction & Financing'!$B$80*E$5)+'Transaction & Financing'!$B$79*'Transaction & Financing'!$B$25)*(1-'Transaction & Financing'!$B$26))/'Accretion-Dilution'!$C$20)/'Accretion-Dilution'!$C$21)-1 -> 0.034558014 | F8: =((('Accretion-Dilution'!$C$6+'Accretion-Dilution'!$C$9+($A8*(1-'Transaction & Financing'!$B$26))-(('Transaction & Financing'!$B$80*'Transaction & Financing'!$B$24)+'Transaction & Financing'!$B$79*'Transaction & Financing'!$B$25)*(1-'Transaction & Financing'!$B$26))/'Accretion-Dilution'!$C$20)/'Accretion-Dilution'!$C$21)-1 -> 0.035502357
A9: ='Transaction & Financing'!$C$65 -> 110.38523 | B9: =((('Accretion-Dilution'!$C$6+'Accretion-Dilution'!$C$9+($A9*(1-'Transaction & Financing'!$B$26))-(('Transaction & Financing'!$B$80*B$5)+'Transaction & Financing'!$B$79*'Transaction & Financing'!$B$25)*(1-'Transaction & Financing'!$B$26))/'Accretion-Dilution'!$C$20)/'Accretion-Dilution'!$C$21)-1 -> 0.039424217 | C9: =((('Accretion-Dilution'!$C$6+'Accretion-Dilution'!$C$9+($A9*(1-'Transaction & Financing'!$B$26))-(('Transaction & Financing'!$B$80*C$5)+'Transaction & Financing'!$B$79*'Transaction & Financing'!$B$25)*(1-'Transaction & Financing'!$B$26))/'Accretion-Dilution'!$C$20)/'Accretion-Dilution'!$C$21)-1 -> 0.038952046 | D9: =((('Accretion-Dilution'!$C$6+'Accretion-Dilution'!$C$9+($A9*(1-'Transaction & Financing'!$B$26))-(('Transaction & Financing'!$B$80*D$5)+'Transaction & Financing'!$B$79*'Transaction & Financing'!$B$25)*(1-'Transaction & Financing'!$B$26))/'Accretion-Dilution'!$C$20)/'Accretion-Dilution'!$C$21)-1 -> 0.038479874 | E9: =((('Accretion-Dilution'!$C$6+'Accretion-Dilution'!$C$9+($A9*(1-'Transaction & Financing'!$B$26))-(('Transaction & Financing'!$B$80*E$5)+'Transaction & Financing'!$B$79*'Transaction & Financing'!$B$25)*(1-'Transaction & Financing'!$B$26))/'Accretion-Dilution'!$C$20)/'Accretion-Dilution'!$C$21)-1 -> 0.038007703 | F9: =((('Accretion-Dilution'!$C$6+'Accretion-Dilution'!$C$9+($A9*(1-'Transaction & Financing'!$B$26))-(('Transaction & Financing'!$B$80*'Transaction & Financing'!$B$24)+'Transaction & Financing'!$B$79*'Transaction & Financing'!$B$25)*(1-'Transaction & Financing'!$B$26))/'Accretion-Dilution'!$C$20)/'Accretion-Dilution'!$C$21)-1 -> 0.038952046
A10: =130 -> 130 | B10: =((('Accretion-Dilution'!$C$6+'Accretion-Dilution'!$C$9+($A10*(1-'Transaction & Financing'!$B$26))-(('Transaction & Financing'!$B$80*B$5)+'Transaction & Financing'!$B$79*'Transaction & Financing'!$B$25)*(1-'Transaction & Financing'!$B$26))/'Accretion-Dilution'!$C$20)/'Accretion-Dilution'!$C$21)-1 -> 0.042006152 | C10: =((('Accretion-Dilution'!$C$6+'Accretion-Dilution'!$C$9+($A10*(1-'Transaction & Financing'!$B$26))-(('Transaction & Financing'!$B$80*C$5)+'Transaction & Financing'!$B$79*'Transaction & Financing'!$B$25)*(1-'Transaction & Financing'!$B$26))/'Accretion-Dilution'!$C$20)/'Accretion-Dilution'!$C$21)-1 -> 0.04153398 | D10: =((('Accretion-Dilution'!$C$6+'Accretion-Dilution'!$C$9+($A10*(1-'Transaction & Financing'!$B$26))-(('Transaction & Financing'!$B$80*D$5)+'Transaction & Financing'!$B$79*'Transaction & Financing'!$B$25)*(1-'Transaction & Financing'!$B$26))/'Accretion-Dilution'!$C$20)/'Accretion-Dilution'!$C$21)-1 -> 0.041061809 | E10: =((('Accretion-Dilution'!$C$6+'Accretion-Dilution'!$C$9+($A10*(1-'Transaction & Financing'!$B$26))-(('Transaction & Financing'!$B$80*E$5)+'Transaction & Financing'!$B$79*'Transaction & Financing'!$B$25)*(1-'Transaction & Financing'!$B$26))/'Accretion-Dilution'!$C$20)/'Accretion-Dilution'!$C$21)-1 -> 0.040589638 | F10: =((('Accretion-Dilution'!$C$6+'Accretion-Dilution'!$C$9+($A10*(1-'Transaction & Financing'!$B$26))-(('Transaction & Financing'!$B$80*'Transaction & Financing'!$B$24)+'Transaction & Financing'!$B$79*'Transaction & Financing'!$B$25)*(1-'Transaction & Financing'!$B$26))/'Accretion-Dilution'!$C$20)/'Accretion-Dilution'!$C$21)-1 -> 0.04153398
A12: Sensitivity Notes
A13: Case range | B13: 0 / low / base / high / $130m synergy cases; base case uses the 15.0x post-synergy multiple.
A14: Financing | B14: Borrowing rate applies to incremental debt; foregone cash yield remains 3.5% on ABB cash used.
A15: Limitations | B15: Excludes purchase accounting, integration costs, dividend effects and changes in diluted share count.
A17: Source Log
A18: ID | B18: Source / date | C18: Data used | D18: URL / reference
A19: S01 | B19: ABB acquisition announcement — 16-Jul-2026 | C19: Offer 503p cash; up to 3p permitted dividend; EV, EV/Sales, EV/EBITDA; synergy language; structure. | D19: https://new.abb.com/news/detail/137499/abb-expands-automation-offering-with-acquisition-of-rotork
A20: S02 | B20: Rotork Scheme Document — 2026 | C20: Unaffected price, VWAPs, premiums, fully diluted shares, equity value, EV bridge, financing provisions. | D20: https://media.rotork.com/api/public/content/a.schemedocument-pdf-ylvrj3qtrymhbohjegna.pdf?v=a93e0be4
A21: S03 | B21: Rotork Results of Meetings — 03-Sep-2026 | C21: Court and shareholder approvals; remaining Court / regulatory conditions; H1 2027 expected effective date; 16-Jul-2027 long-stop. | D21: https://media.rotork.com/api/public/content/f.resultsofshareholderandcourtmeetings-downloadoriginal-ohnc7wx5rkaxb6iemvsb.pdf?v=41ec5c96
A22: S04 | B22: Rotork H1 2026 results — 30-Jun-2026 | C22: H1 revenue, adjusted operating profit, profit, EPS, cash, debt, leases, tax and diluted shares. | D22: https://media.rotork.com/api/public/content/pub082-420-halfyearresultspressrelease2026-pdf-yuq9oivmtso6wjckhxrt.pdf?v=0b70320b
A23: S05 | B23: Rotork FY2025 press release — 2026 | C23: FY25 / FY24 revenue, operating profit, EBITDA bridge inputs, net income, EPS and cash / debt. | D23: https://media.rotork.com/api/public/content/rotorkfy2025pressrelease-downloadoriginal-nmcispv8svefnc2ppzej.pdf?v=14606f38
A24: S06 | B24: ABB Q2 2026 results — 23-Jul-2026 | C24: H1 2026 revenue, EBITA, income from operations, net income, EPS, cash, securities and debt. | D24: https://www.abb.com/global/en/news/137496/q2-2026-results
A25: S07 | B25: ABB Financial Report 2025 | C25: FY25 / FY24 revenue, income from operations, EBITA, net income, EPS, cash, securities and debt. | D25: https://library.e.abb.com/public/b32991481e8b4418a5c5261c5ff25440/ABB%20Financial%20Report%202025.pdf
A26: S08 | B26: ABB Q2 2026 results — Robotics disposal | C26: Expected net cash proceeds of approximately $4.8bn used as a funding source assumption. | D26: https://www.abb.com/global/en/news/137496/q2-2026-results
A27: S09 | B27: GBP / USD spot — 16-Jul-2026 | C27: Transaction-date FX rate of 1.34757 USD per GBP for converted transaction values. | D27: https://www.exchange-rates.org/exchange-rate-history/gbp-usd-2026-07-16
A28: S10 | B28: Transaction fees — analyst assumption | C28: Modeled $25m fees; editable in Transaction & Financing!B11. | D28: Analyst assumption; no external source.
A29: S11 | B29: ABB cash used — analyst assumption | C29: Modeled $500m ABB cash contribution; editable in Transaction & Financing!B22. | D29: Analyst assumption; no external source.
... A38: S20 | B38: Model date | C38: As-of date is 06-Sep-2026; meetings approved 03-Sep-2026 and remaining conditions are outstanding. | D38: S03.
